<?xml version="1.0" encoding="utf-8"?>
<!-- =================================================================================== -->
<!-- |    This document was autogenerated by xacro from spot.urdf.xacro                | -->
<!-- |    EDITING THIS FILE BY HAND IS NOT RECOMMENDED                                 | -->
<!-- =================================================================================== -->
<robot name="spot">
  <link name="body">
    <visual>
      <geometry>
        <mesh filename="package://spot_description/meshes/body.dae"/>
      </geometry>
    </visual>
    <collision>
      <geometry>
        <mesh filename="package://spot_description/meshes/body_collision.stl"/>
      </geometry>
    </collision>
    <inertial>
      <mass value="16.0"/>
      <inertia ixx="0.0973333333333" ixy="0.0" ixz="0.0" iyy="1.02466666667" iyz="0.0" izz="1.04493333333"/>
    </inertial>
  </link>
  <link name="base_link"/>
  <joint name="base_link_joint" type="fixed">
    <origin rpy="0 0 0" xyz="0 0 0"/>
    <parent link="body"/>
    <child link="base_link"/>
  </joint>
  <link name="front_rail"/>
  <joint name="front_rail_joint" type="fixed">
    <origin rpy="0 0 0" xyz="0.223 0 0.0805"/>
    <parent link="body"/>
    <child link="front_rail"/>
  </joint>
  <link name="rear_rail"/>
  <joint name="rear_rail_joint" type="fixed">
    <origin rpy="0 0 0" xyz="-0.223 0 0.0805"/>
    <parent link="body"/>
    <child link="rear_rail"/>
  </joint>
  <!-- This file is a placeholder which is included by default from
       spot.urdf.xacro. If a robot is being customized and requires
       additional URDF, set the SPOT_URDF_EXTRAS environment variable
       to the full path of the file you would like included. -->
  <joint name="hokuyo_joint" type="fixed">
    <origin rpy="0 0 0" xyz="0.0 0.0 0.125"/>
    <parent link="base_link"/>
    <child link="hokuyo_frame"/>
  </joint>
  <link name="hokuyo_frame">
    <inertial>
      <mass value="0.270"/>
      <origin rpy="0 0 0" xyz="0 0 0"/>
      <inertia ixx="2.632e-4" ixy="0" ixz="0" iyy="2.632e-4" iyz="0" izz="1.62e-4"/>
    </inertial>
    <visual>
      <origin rpy="0 0 0" xyz="0 0 0"/>
      <geometry>
        <mesh filename="package://hector_sensors_description/meshes/hokuyo_utm30lx/hokuyo_utm_30lx.dae"/>
      </geometry>
    </visual>
    <collision>
      <origin rpy="0 0 0" xyz="0 0 -0.0115"/>
      <geometry>
        <box size="0.058 0.058 0.087"/>
        <!--<mesh filename="package://hector_sensors_description/meshes/hokuyo_utm30lx/hokuyo_utm_30lx.stl"/>-->
      </geometry>
    </collision>
  </link>
  <gazebo reference="hokuyo_frame">
    <sensor name="hokuyo" type="ray">
      <always_on>true</always_on>
      <update_rate>30</update_rate>
      <pose>0 0 0 0 0 0</pose>
      <visualize>false</visualize>
      <ray>
        <scan>
          <horizontal>
            <samples>1040</samples>
            <resolution>1</resolution>
            <min_angle>2.26892802759</min_angle>
            <max_angle>-2.26892802759</max_angle>
          </horizontal>
        </scan>
        <range>
          <min>0.2</min>
          <max>30.0</max>
          <resolution>0.01</resolution>
        </range>
        <noise>
          <type>gaussian</type>
          <mean>0.0</mean>
          <stddev>0.004</stddev>
        </noise>
      </ray>
      <plugin filename="libgazebo_ros_laser.so" name="gazebo_ros_hokuyo_controller">
        <topicName>scan</topicName>
        <frameName>hokuyo_frame</frameName>
      </plugin>
    </sensor>
  </gazebo>
  <gazebo reference="hokuyo_frame">
    <material>Gazebo/FlatBlack</material>
  </gazebo>
  <joint name="camera_joint" type="fixed">
    <origin rpy="0 0 0" xyz="0.38 0.0 -0.095"/>
    <parent link="base_link"/>
    <child link="camera_link"/>
  </joint>
  <link name="camera_link">
    <inertial>
      <mass value="0.200"/>
      <origin rpy="0 0 0" xyz="0 0 0"/>
      <inertia ixx="5.8083e-4" ixy="0" ixz="0" iyy="3.0833e-5" iyz="0" izz="5.9083e-4"/>
    </inertial>
    <visual>
      <origin rpy="0 0 0" xyz="0 0 0"/>
      <geometry>
        <mesh filename="package://hector_sensors_description/meshes/asus_camera/asus_camera_simple.dae"/>
      </geometry>
    </visual>
    <!--        
       <collision>
          <origin xyz="0 0 0" rpy="0 0 0" />
          <geometry>
            <box size="0.035 0.185 0.025"/>
          </geometry>
        </collision>
        -->
    <collision>
      <origin rpy="0 0 0" xyz="0 0 0"/>
      <geometry>
        <mesh filename="package://hector_sensors_description/meshes/asus_camera/asus_camera_simple.dae"/>
      </geometry>
    </collision>
  </link>
  <joint name="camera_depth_joint" type="fixed">
    <origin rpy="0 0 0" xyz="0.0 0.049 0.0"/>
    <parent link="camera_link"/>
    <child link="camera_depth_frame"/>
  </joint>
  <link name="camera_depth_frame"/>
  <joint name="camera_depth_optical_joint" type="fixed">
    <origin rpy="-1.57079632679 0.0 -1.57079632679" xyz="0 0 0"/>
    <parent link="camera_depth_frame"/>
    <child link="camera_depth_optical_frame"/>
  </joint>
  <link name="camera_depth_optical_frame"/>
  <joint name="camera_rgb_joint" type="fixed">
    <origin rpy="0 0 0" xyz="0.0 0.022 0.0"/>
    <parent link="camera_link"/>
    <child link="camera_rgb_frame"/>
  </joint>
  <link name="camera_rgb_frame"/>
  <joint name="camera_rgb_optical_joint" type="fixed">
    <origin rpy="-1.57079632679 0.0 -1.57079632679" xyz="0 0 0"/>
    <parent link="camera_rgb_frame"/>
    <child link="camera_rgb_optical_frame"/>
  </joint>
  <link name="camera_rgb_optical_frame"/>
  <!-- ASUS Xtion PRO camera for simulation -->
  <gazebo reference="camera_depth_frame">
    <sensor name="camera" type="depth">
      <update_rate>20</update_rate>
      <camera>
        <horizontal_fov>1.09606677025</horizontal_fov>
        <image>
          <format>R8G8B8</format>
          <width>640</width>
          <height>480</height>
        </image>
        <clip>
          <near>0.5</near>
          <far>9</far>
        </clip>
      </camera>
      <plugin filename="libgazebo_ros_openni_kinect.so" name="camera_camera_controller">
        <imageTopicName>camera/rgb/image_raw</imageTopicName>
        <cameraInfoTopicName>camera/rgb/camera_info</cameraInfoTopicName>
        <depthImageTopicName>camera/depth/image_raw</depthImageTopicName>
        <depthImageCameraInfoTopicName>camera/depth/camera_info</depthImageCameraInfoTopicName>
        <pointCloudTopicName>camera/depth/points</pointCloudTopicName>
        <frameName>camera_depth_optical_frame</frameName>
      </plugin>
    </sensor>
  </gazebo>
  <gazebo>
    <plugin filename="libhector_gazebo_ros_imu.so" name="imu_controller">
      <updateRate>50.0</updateRate>
      <bodyName>imu_link</bodyName>
      <topicName>imu/data</topicName>
      <accelDrift>0.005 0.005 0.005</accelDrift>
      <accelGaussianNoise>0.005 0.005 0.005</accelGaussianNoise>
      <rateDrift>0.005 0.005 0.005 </rateDrift>
      <rateGaussianNoise>0.005 0.005 0.005 </rateGaussianNoise>
      <headingDrift>0.005</headingDrift>
      <headingGaussianNoise>0.005</headingGaussianNoise>
    </plugin>
  </gazebo>
  <link name="imu_link">
    <inertial>
      <mass value="0.001"/>
      <origin rpy="0 0 0" xyz="0 0 0"/>
      <inertia ixx="1e-09" ixy="0.0" ixz="0.0" iyy="1e-09" iyz="0.0" izz="1e-09"/>
    </inertial>
  </link>
  <joint name="imu_joint" type="fixed">
    <parent link="base_link"/>
    <child link="imu_link"/>
  </joint>
  <!-- <xacro:include filename="$(find velodyne_description)/urdf/VLP-16.urdf.xacro"/>
    <xacro:VLP-16 parent="base_link" name="velodyne" topic="velodyne_points" hz="10" samples="1024" gpu="false" lasers="16" max_range="100">
        <origin xyz="0.29 0 ${(base_height / 2) - 0.01}" rpy="0 0 0" />
    </xacro:VLP-16> -->
  <link name="front_left_hip">
    <visual>
      <geometry>
        <mesh filename="package://spot_description/meshes/front_left_hip.dae"/>
      </geometry>
    </visual>
    <collision>
      <geometry>
        <mesh filename="package://spot_description/meshes/front_left_hip_collision.stl"/>
      </geometry>
    </collision>
    <inertial>
      <mass value="2.0"/>
      <inertia ixx="0.0027" ixy="0.0" ixz="0.0" iyy="0.00416666666667" iyz="0.0" izz="0.00416666666667"/>
    </inertial>
  </link>
  <joint name="front_left_hip_x" type="revolute">
    <origin rpy="0 0 0" xyz="0.29785 0.055 0"/>
    <axis xyz="1 0 0"/>
    <parent link="body"/>
    <child link="front_left_hip"/>
    <limit effort="100" lower="-0.78539816339744827899" upper="0.78539816339744827899" velocity="1000.00"/>
  </joint>
  <link name="front_left_upper_leg">
    <visual>
      <geometry>
        <mesh filename="package://spot_description/meshes/front_left_upper_leg.dae"/>
      </geometry>
    </visual>
    <collision>
      <geometry>
        <mesh filename="package://spot_description/meshes/front_left_upper_leg_collision.stl"/>
      </geometry>
    </collision>
    <inertial>
      <origin rpy="0 0 0" xyz="0 0 -0.14"/>
      <mass value="1.0"/>
      <inertia ixx="0.0155334166667" ixy="0.0" ixz="0.0" iyy="0.0155334166667" iyz="0.0" izz="0.000962666666667"/>
    </inertial>
  </link>
  <joint name="front_left_hip_y" type="revolute">
    <origin rpy="0 0 0" xyz="0 0.110945 0"/>
    <axis xyz="0 1 0"/>
    <parent link="front_left_hip"/>
    <child link="front_left_upper_leg"/>
    <limit effort="100" lower="-0.89884456477707963539" upper="2.2951079663725435509" velocity="1000.00"/>
  </joint>
  <link name="front_left_lower_leg">
    <visual>
      <geometry>
        <mesh filename="package://spot_description/meshes/front_left_lower_leg.dae"/>
      </geometry>
    </visual>
    <collision>
      <geometry>
        <mesh filename="package://spot_description/meshes/front_left_lower_leg_collision.stl" scale="0.82 0.97 0.98"/>
      </geometry>
    </collision>
    <inertial>
      <origin rpy="0 0 0" xyz="0 0 -0.16"/>
      <mass value="0.5"/>
      <inertia ixx="0.007434375" ixy="0.0" ixz="0.0" iyy="0.00740104166667" iyz="0.0" izz="0.000135416666667"/>
    </inertial>
  </link>
  <gazebo reference="front_left_lower_leg">
    <kp>100000.0</kp>
    <kd>1.0</kd>
    <mu1>0.8</mu1>
    <mu2>0.8</mu2>
    <maxVel>0.0</maxVel>
    <minDepth>0.001</minDepth>
  </gazebo>
  <joint name="front_left_knee" type="revolute">
    <origin rpy="0 0 0" xyz="0.025 0 -0.3205"/>
    <axis xyz="0 1 0"/>
    <parent link="front_left_upper_leg"/>
    <child link="front_left_lower_leg"/>
    <limit effort="100" lower="-2.7929" upper="-0.254801" velocity="1000.00"/>
  </joint>
  <link name="front_left_ee"/>
  <joint name="front_left_foot" type="fixed">
    <parent link="front_left_lower_leg"/>
    <child link="front_left_ee"/>
    <origin rpy="0 0 0" xyz="0 0 -0.37"/>
  </joint>
  <transmission name="front_left_hip_x_trans">
    <type>transmission_interface/SimpleTransmission</type>
    <joint name="front_left_hip_x">
      <hardwareInterface>hardware_interface/EffortJointInterface</hardwareInterface>
    </joint>
    <actuator name="front_left_hip_x_actuator">
      <hardwareInterface>hardware_interface/EffortJointInterface</hardwareInterface>
      <mechanicalReduction>1</mechanicalReduction>
    </actuator>
  </transmission>
  <transmission name="front_left_hip_y_trans">
    <type>transmission_interface/SimpleTransmission</type>
    <joint name="front_left_hip_y">
      <hardwareInterface>hardware_interface/EffortJointInterface</hardwareInterface>
    </joint>
    <actuator name="front_left_hip_y_actuator">
      <hardwareInterface>hardware_interface/EffortJointInterface</hardwareInterface>
      <mechanicalReduction>1</mechanicalReduction>
    </actuator>
  </transmission>
  <transmission name="front_left_knee_trans">
    <type>transmission_interface/SimpleTransmission</type>
    <joint name="front_left_knee">
      <hardwareInterface>hardware_interface/EffortJointInterface</hardwareInterface>
    </joint>
    <actuator name="front_left_knee_actuator">
      <hardwareInterface>hardware_interface/EffortJointInterface</hardwareInterface>
      <mechanicalReduction>1</mechanicalReduction>
    </actuator>
  </transmission>
  <link name="front_right_hip">
    <visual>
      <geometry>
        <mesh filename="package://spot_description/meshes/front_right_hip.dae"/>
      </geometry>
    </visual>
    <collision>
      <geometry>
        <mesh filename="package://spot_description/meshes/front_right_hip_collision.stl"/>
      </geometry>
    </collision>
    <inertial>
      <mass value="2.0"/>
      <inertia ixx="0.0027" ixy="0.0" ixz="0.0" iyy="0.00416666666667" iyz="0.0" izz="0.00416666666667"/>
    </inertial>
  </link>
  <joint name="front_right_hip_x" type="revolute">
    <origin rpy="0 0 0" xyz="0.29785 -0.055 0"/>
    <axis xyz="1 0 0"/>
    <parent link="body"/>
    <child link="front_right_hip"/>
    <limit effort="100" lower="-0.78539816339744827899" upper="0.78539816339744827899" velocity="1000.00"/>
  </joint>
  <link name="front_right_upper_leg">
    <visual>
      <geometry>
        <mesh filename="package://spot_description/meshes/front_right_upper_leg.dae"/>
      </geometry>
    </visual>
    <collision>
      <geometry>
        <mesh filename="package://spot_description/meshes/front_right_upper_leg_collision.stl"/>
      </geometry>
    </collision>
    <inertial>
      <origin rpy="0 0 0" xyz="0 0 -0.14"/>
      <mass value="1.0"/>
      <inertia ixx="0.0155334166667" ixy="0.0" ixz="0.0" iyy="0.0155334166667" iyz="0.0" izz="0.000962666666667"/>
    </inertial>
  </link>
  <joint name="front_right_hip_y" type="revolute">
    <origin rpy="0 0 0" xyz="0 -0.110945 0"/>
    <axis xyz="0 1 0"/>
    <parent link="front_right_hip"/>
    <child link="front_right_upper_leg"/>
    <limit effort="100" lower="-0.89884456477707963539" upper="2.2951079663725435509" velocity="1000.00"/>
  </joint>
  <link name="front_right_lower_leg">
    <visual>
      <geometry>
        <mesh filename="package://spot_description/meshes/front_right_lower_leg.dae"/>
      </geometry>
    </visual>
    <collision>
      <geometry>
        <mesh filename="package://spot_description/meshes/front_right_lower_leg_collision.stl" scale="0.82 0.97 0.98"/>
      </geometry>
    </collision>
    <inertial>
      <origin rpy="0 0 0" xyz="0 0 -0.16"/>
      <mass value="0.5"/>
      <inertia ixx="0.007434375" ixy="0.0" ixz="0.0" iyy="0.00740104166667" iyz="0.0" izz="0.000135416666667"/>
    </inertial>
  </link>
  <gazebo reference="front_right_lower_leg">
    <kp>100000.0</kp>
    <kd>1.0</kd>
    <mu1>0.8</mu1>
    <mu2>0.8</mu2>
    <maxVel>0.0</maxVel>
    <minDepth>0.001</minDepth>
  </gazebo>
  <joint name="front_right_knee" type="revolute">
    <origin rpy="0 0 0" xyz="0.025 0 -0.3205"/>
    <axis xyz="0 1 0"/>
    <parent link="front_right_upper_leg"/>
    <child link="front_right_lower_leg"/>
    <limit effort="100" lower="-2.7929" upper="-0.254801" velocity="1000.00"/>
  </joint>
  <link name="front_right_ee"/>
  <joint name="front_right_foot" type="fixed">
    <parent link="front_right_lower_leg"/>
    <child link="front_right_ee"/>
    <origin rpy="0 0 0" xyz="0 0 -0.37"/>
  </joint>
  <transmission name="front_right_hip_x_trans">
    <type>transmission_interface/SimpleTransmission</type>
    <joint name="front_right_hip_x">
      <hardwareInterface>hardware_interface/EffortJointInterface</hardwareInterface>
    </joint>
    <actuator name="front_right_hip_x_actuator">
      <hardwareInterface>hardware_interface/EffortJointInterface</hardwareInterface>
      <mechanicalReduction>1</mechanicalReduction>
    </actuator>
  </transmission>
  <transmission name="front_right_hip_y_trans">
    <type>transmission_interface/SimpleTransmission</type>
    <joint name="front_right_hip_y">
      <hardwareInterface>hardware_interface/EffortJointInterface</hardwareInterface>
    </joint>
    <actuator name="front_right_hip_y_actuator">
      <hardwareInterface>hardware_interface/EffortJointInterface</hardwareInterface>
      <mechanicalReduction>1</mechanicalReduction>
    </actuator>
  </transmission>
  <transmission name="front_right_knee_trans">
    <type>transmission_interface/SimpleTransmission</type>
    <joint name="front_right_knee">
      <hardwareInterface>hardware_interface/EffortJointInterface</hardwareInterface>
    </joint>
    <actuator name="front_right_knee_actuator">
      <hardwareInterface>hardware_interface/EffortJointInterface</hardwareInterface>
      <mechanicalReduction>1</mechanicalReduction>
    </actuator>
  </transmission>
  <link name="rear_left_hip">
    <visual>
      <geometry>
        <mesh filename="package://spot_description/meshes/rear_left_hip.dae"/>
      </geometry>
    </visual>
    <collision>
      <geometry>
        <mesh filename="package://spot_description/meshes/rear_left_hip_collision.stl"/>
      </geometry>
    </collision>
    <inertial>
      <mass value="2.0"/>
      <inertia ixx="0.0027" ixy="0.0" ixz="0.0" iyy="0.00416666666667" iyz="0.0" izz="0.00416666666667"/>
    </inertial>
  </link>
  <joint name="rear_left_hip_x" type="revolute">
    <origin rpy="0 0 0" xyz="-0.29785 0.055 0"/>
    <axis xyz="1 0 0"/>
    <parent link="body"/>
    <child link="rear_left_hip"/>
    <limit effort="100" lower="-0.78539816339744827899" upper="0.78539816339744827899" velocity="1000.00"/>
  </joint>
  <link name="rear_left_upper_leg">
    <visual>
      <geometry>
        <mesh filename="package://spot_description/meshes/rear_left_upper_leg.dae"/>
      </geometry>
    </visual>
    <collision>
      <geometry>
        <mesh filename="package://spot_description/meshes/rear_left_upper_leg_collision.stl"/>
      </geometry>
    </collision>
    <inertial>
      <origin rpy="0 0 0" xyz="0 0 -0.14"/>
      <mass value="1.0"/>
      <inertia ixx="0.0155334166667" ixy="0.0" ixz="0.0" iyy="0.0155334166667" iyz="0.0" izz="0.000962666666667"/>
    </inertial>
  </link>
  <joint name="rear_left_hip_y" type="revolute">
    <origin rpy="0 0 0" xyz="0 0.110945 0"/>
    <axis xyz="0 1 0"/>
    <parent link="rear_left_hip"/>
    <child link="rear_left_upper_leg"/>
    <limit effort="100" lower="-0.89884456477707963539" upper="2.2951079663725435509" velocity="1000.00"/>
  </joint>
  <link name="rear_left_lower_leg">
    <visual>
      <geometry>
        <mesh filename="package://spot_description/meshes/rear_left_lower_leg.dae"/>
      </geometry>
    </visual>
    <collision>
      <geometry>
        <mesh filename="package://spot_description/meshes/rear_left_lower_leg_collision.stl" scale="0.82 0.97 0.98"/>
      </geometry>
    </collision>
    <inertial>
      <origin rpy="0 0 0" xyz="0 0 -0.16"/>
      <mass value="0.5"/>
      <inertia ixx="0.007434375" ixy="0.0" ixz="0.0" iyy="0.00740104166667" iyz="0.0" izz="0.000135416666667"/>
    </inertial>
  </link>
  <gazebo reference="rear_left_lower_leg">
    <kp>100000.0</kp>
    <kd>1.0</kd>
    <mu1>0.8</mu1>
    <mu2>0.8</mu2>
    <maxVel>0.0</maxVel>
    <minDepth>0.001</minDepth>
  </gazebo>
  <joint name="rear_left_knee" type="revolute">
    <origin rpy="0 0 0" xyz="0.025 0 -0.3205"/>
    <axis xyz="0 1 0"/>
    <parent link="rear_left_upper_leg"/>
    <child link="rear_left_lower_leg"/>
    <limit effort="100" lower="-2.7929" upper="-0.254801" velocity="1000.00"/>
  </joint>
  <link name="rear_left_ee"/>
  <joint name="rear_left_foot" type="fixed">
    <parent link="rear_left_lower_leg"/>
    <child link="rear_left_ee"/>
    <origin rpy="0 0 0" xyz="0 0 -0.37"/>
  </joint>
  <transmission name="rear_left_hip_x_trans">
    <type>transmission_interface/SimpleTransmission</type>
    <joint name="rear_left_hip_x">
      <hardwareInterface>hardware_interface/EffortJointInterface</hardwareInterface>
    </joint>
    <actuator name="rear_left_hip_x_actuator">
      <hardwareInterface>hardware_interface/EffortJointInterface</hardwareInterface>
      <mechanicalReduction>1</mechanicalReduction>
    </actuator>
  </transmission>
  <transmission name="rear_left_hip_y_trans">
    <type>transmission_interface/SimpleTransmission</type>
    <joint name="rear_left_hip_y">
      <hardwareInterface>hardware_interface/EffortJointInterface</hardwareInterface>
    </joint>
    <actuator name="rear_left_hip_y_actuator">
      <hardwareInterface>hardware_interface/EffortJointInterface</hardwareInterface>
      <mechanicalReduction>1</mechanicalReduction>
    </actuator>
  </transmission>
  <transmission name="rear_left_knee_trans">
    <type>transmission_interface/SimpleTransmission</type>
    <joint name="rear_left_knee">
      <hardwareInterface>hardware_interface/EffortJointInterface</hardwareInterface>
    </joint>
    <actuator name="rear_left_knee_actuator">
      <hardwareInterface>hardware_interface/EffortJointInterface</hardwareInterface>
      <mechanicalReduction>1</mechanicalReduction>
    </actuator>
  </transmission>
  <link name="rear_right_hip">
    <visual>
      <geometry>
        <mesh filename="package://spot_description/meshes/rear_right_hip.dae"/>
      </geometry>
    </visual>
    <collision>
      <geometry>
        <mesh filename="package://spot_description/meshes/rear_right_hip_collision.stl"/>
      </geometry>
    </collision>
    <inertial>
      <mass value="2.0"/>
      <inertia ixx="0.0027" ixy="0.0" ixz="0.0" iyy="0.00416666666667" iyz="0.0" izz="0.00416666666667"/>
    </inertial>
  </link>
  <joint name="rear_right_hip_x" type="revolute">
    <origin rpy="0 0 0" xyz="-0.29785 -0.055 0"/>
    <axis xyz="1 0 0"/>
    <parent link="body"/>
    <child link="rear_right_hip"/>
    <limit effort="100" lower="-0.78539816339744827899" upper="0.78539816339744827899" velocity="1000.00"/>
  </joint>
  <link name="rear_right_upper_leg">
    <visual>
      <geometry>
        <mesh filename="package://spot_description/meshes/rear_right_upper_leg.dae"/>
      </geometry>
    </visual>
    <collision>
      <geometry>
        <mesh filename="package://spot_description/meshes/rear_right_upper_leg_collision.stl"/>
      </geometry>
    </collision>
    <inertial>
      <origin rpy="0 0 0" xyz="0 0 -0.14"/>
      <mass value="1.0"/>
      <inertia ixx="0.0155334166667" ixy="0.0" ixz="0.0" iyy="0.0155334166667" iyz="0.0" izz="0.000962666666667"/>
    </inertial>
  </link>
  <joint name="rear_right_hip_y" type="revolute">
    <origin rpy="0 0 0" xyz="0 -0.110945 0"/>
    <axis xyz="0 1 0"/>
    <parent link="rear_right_hip"/>
    <child link="rear_right_upper_leg"/>
    <limit effort="100" lower="-0.89884456477707963539" upper="2.2951079663725435509" velocity="1000.00"/>
  </joint>
  <link name="rear_right_lower_leg">
    <visual>
      <geometry>
        <mesh filename="package://spot_description/meshes/rear_right_lower_leg.dae"/>
      </geometry>
    </visual>
    <collision>
      <geometry>
        <mesh filename="package://spot_description/meshes/rear_right_lower_leg_collision.stl" scale="0.82 0.97 0.98"/>
      </geometry>
    </collision>
    <inertial>
      <origin rpy="0 0 0" xyz="0 0 -0.16"/>
      <mass value="0.5"/>
      <inertia ixx="0.007434375" ixy="0.0" ixz="0.0" iyy="0.00740104166667" iyz="0.0" izz="0.000135416666667"/>
    </inertial>
  </link>
  <gazebo reference="rear_right_lower_leg">
    <kp>100000.0</kp>
    <kd>1.0</kd>
    <mu1>0.8</mu1>
    <mu2>0.8</mu2>
    <maxVel>0.0</maxVel>
    <minDepth>0.001</minDepth>
  </gazebo>
  <joint name="rear_right_knee" type="revolute">
    <origin rpy="0 0 0" xyz="0.025 0 -0.3205"/>
    <axis xyz="0 1 0"/>
    <parent link="rear_right_upper_leg"/>
    <child link="rear_right_lower_leg"/>
    <limit effort="100" lower="-2.7929" upper="-0.254801" velocity="1000.00"/>
  </joint>
  <link name="rear_right_ee"/>
  <joint name="rear_right_foot" type="fixed">
    <parent link="rear_right_lower_leg"/>
    <child link="rear_right_ee"/>
    <origin rpy="0 0 0" xyz="0 0 -0.37"/>
  </joint>
  <transmission name="rear_right_hip_x_trans">
    <type>transmission_interface/SimpleTransmission</type>
    <joint name="rear_right_hip_x">
      <hardwareInterface>hardware_interface/EffortJointInterface</hardwareInterface>
    </joint>
    <actuator name="rear_right_hip_x_actuator">
      <hardwareInterface>hardware_interface/EffortJointInterface</hardwareInterface>
      <mechanicalReduction>1</mechanicalReduction>
    </actuator>
  </transmission>
  <transmission name="rear_right_hip_y_trans">
    <type>transmission_interface/SimpleTransmission</type>
    <joint name="rear_right_hip_y">
      <hardwareInterface>hardware_interface/EffortJointInterface</hardwareInterface>
    </joint>
    <actuator name="rear_right_hip_y_actuator">
      <hardwareInterface>hardware_interface/EffortJointInterface</hardwareInterface>
      <mechanicalReduction>1</mechanicalReduction>
    </actuator>
  </transmission>
  <transmission name="rear_right_knee_trans">
    <type>transmission_interface/SimpleTransmission</type>
    <joint name="rear_right_knee">
      <hardwareInterface>hardware_interface/EffortJointInterface</hardwareInterface>
    </joint>
    <actuator name="rear_right_knee_actuator">
      <hardwareInterface>hardware_interface/EffortJointInterface</hardwareInterface>
      <mechanicalReduction>1</mechanicalReduction>
    </actuator>
  </transmission>
  <gazebo>
    <plugin filename="libgazebo_ros_p3d.so" name="p3d_base_controller">
      <alwaysOn>true</alwaysOn>
      <updateRate>10.0</updateRate>
      <bodyName>base_link</bodyName>
      <topicName>odom/ground_truth</topicName>
      <gaussianNoise>0.01</gaussianNoise>
      <frameName>world</frameName>
      <xyzOffsets>0 0 0</xyzOffsets>
      <rpyOffsets>0 0 0</rpyOffsets>
    </plugin>
  </gazebo>
  <gazebo>
    <plugin filename="libgazebo_ros_control.so" name="gazebo_ros_control">
      <legacyModeNS>true</legacyModeNS>
    </plugin>
  </gazebo>
</robot>

